Workbook

Sheet Instruções
A1: Planilha de Arrecadação da Festa — EM Regina Celi da Silva Cerdeira
A4: Esta planilha reúne a transcrição das anotações manuscritas (cadernos de vendas) referentes à arrecadação da festa, conforme as 19 páginas/fotos enviadas em 20/07/2026.
A6: IMPORTANTE — Sobre a transcrição:
A7: As anotações originais são manuscritas, em cadernos de rascunho, com muitas abreviações (pix, dinh., déb., créd.), valores emendados, rasuras e somas manuais. Foi feito o melhor esforço de leitura e organização de cada valor e forma de pagamento. Ainda assim, RECOMENDA-SE que a Direção/Coordenação confira os valores desta planilha com os cadernos originais antes de usá-la como documento oficial de prestação de contas, especialmente os itens marcados com a observação 'conferir'.
A9: Estrutura da planilha:
A10: • Vendas Detalhadas — itens vendidos, valor e forma de pagamento, por página de origem.
A11: • Consumo Interno (Equipe) — itens consumidos por professores, mediadores(as) e colaboradores.
A12: • Extrato Maquininha — sequência de lançamentos de débito/crédito da maquininha de cartão.
A13: • Doações — valores doados por apoiadores, somados como entrada inicial de caixa da festa.
A14: • Fechamento de Caixa — resumo final: dinheiro em espécie, maquininha, Pix, doações e despesas.
A15: • Despesas da Festa — despesas que antecederam e sucederam o evento.
A16: • Resumo Geral — totais consolidados por forma de pagamento e resultado líquido da festa.
... A26: 7. NOVO — Retirados do custo das bebidas os valores da cerveja Heineken (R$ 268,00) e do chopp de vinho Bodegão (R$ 113,40), pagos à parte e não somados às despesas da festa. O detalhamento permanece registrado na aba 'Despesas da Festa' apenas como referência (não entra nos totais).

Sheet Índice de Páginas
A1: Índice de Páginas (Origem das Fotos)
A2: Página (nesta planilha) | B2: Arquivo original | C2: Conteúdo
A3: 1 | B3: IMG-20260720-WA0030.jpg | C3: Lista de valores recebidos por venda (sem detalhar item), com forma de pagamento; anotações de saída de caixa (Bianca).
A4: 2 | B4: IMG-20260720-WA0020.jpg | C4: Vendas detalhadas por barraca (comidas/bebidas/brincadeiras) com totais por forma de pagamento.
A5: 3 | B5: IMG-20260720-WA0023.jpg | C5: Vendas detalhadas por barraca (pastéis, salgados, refrigerantes, brincadeiras).
A6: 4 | B6: IMG-20260720-WA0022.jpg | C6: Pequena tabela de vendas avulsas (cachorro-quente, salgados, refrigerante, brincadeira).
A7: 5 | B7: IMG-20260720-WA0018.jpg | C7: Vendas detalhadas em tabela (pastéis, salgados, guaraná, refrigerantes, caldos, brincadeiras).
A8: 6 | B8: IMG-20260720-WA0019.jpg | C8: Vendas detalhadas, parte em tinta preta e parte em vermelho (lançamentos adicionais).
A9: 7 | B9: IMG-20260720-WA0015.jpg | C9: Vendas detalhadas com nomes de responsáveis (ex.: mãe da Ana Laura) e cortesias.
A10: 8 | B10: IMG-20260720-WA0029.jpg | C10: Consumo interno por nome — professoras, mediadoras, monitoras e colaboradores.
A11: 9 | B11: IMG-20260720-WA0016.jpg | C11: Lista de vendas com totais por forma de pagamento (Pix, débito, crédito).
A12: 10 | B12: IMG-20260720-WA0017.jpg | C12: Vendas detalhadas com registros de devolução (maçã, salgado, pastel).
A13: 11 | B13: IMG-20260720-WA0028.jpg | C13: Consumo interno por nome (Rosemary, Rose, Lu, Lili) — página parcialmente decalcada/apagada.
A14: 12 | B14: IMG-20260720-WA0014.jpg | C14: FECHAMENTO DE CAIXA: dinheiro em espécie, maquininha (Elaine), Pix (Mario), despesas (tenda, foto, mercado).
... A21: 19 | B21: IMG-20260720-WA0024.jpg | C21: Vendas detalhadas com totais por forma de pagamento, incluindo créditos e débitos.

Sheet Vendas Detalhadas
A1: Vendas Detalhadas
A2: Nº | B2: Página | C2: Itens Vendidos | D2: Valor (R$) | E2: Forma de Pagamento | F2: Observação
A3: 1 | B3: 1 | C3: Venda avulsa (item não detalhado) | D3: 18 | E3: Pix
A4: 2 | B4: 1 | C4: Venda avulsa (item não detalhado) | D4: 11 | E4: Pix
A5: 3 | B5: 1 | C5: Venda avulsa (item não detalhado) | D5: 5 | E5: Dinheiro
A6: 4 | B6: 1 | C6: Venda avulsa (item não detalhado) | D6: 12 | E6: Pix
A7: 5 | B7: 1 | C7: Venda avulsa (item não detalhado) | D7: 5 | E7: Dinheiro
A8: 6 | B8: 1 | C8: Venda avulsa (item não detalhado) | D8: 4 | E8: Dinheiro
A9: 7 | B9: 1 | C9: Venda avulsa (item não detalhado) | D9: 4 | E9: Dinheiro
A10: 8 | B10: 1 | C10: Venda avulsa (item não detalhado) | D10: 4 | E10: Pix | F10: rasura sobre o valor
A11: 9 | B11: 1 | C11: Venda avulsa (item não detalhado) | D11: 12 | E11: Dinheiro
A12: 10 | B12: 1 | C12: Venda avulsa (item não detalhado) | D12: 20 | E12: Dinheiro
A13: 11 | B13: 1 | C13: Venda avulsa (item não detalhado) | D13: 8 | E13: Dinheiro
A14: 12 | B14: 1 | C14: Venda avulsa (item não detalhado) | D14: 4 | E14: Dinheiro
A15: 13 | B15: 1 | C15: Venda avulsa (item não detalhado) | D15: 11 | E15: Dinheiro
A16: 14 | B16: 1 | C16: Venda avulsa (item não detalhado) | D16: 8 | E16: Pix
A17: 15 | B17: 1 | C17: Venda avulsa (item não detalhado) | D17: 7 | E17: Pix
A18: 16 | B18: 1 | C18: Venda avulsa (item não detalhado) | D18: 8 | E18: Pix
A19: 17 | B19: 1 | C19: Venda avulsa (item não detalhado) | D19: 7 | E19: Pix
A20: 18 | B20: 1 | C20: Venda avulsa (item não detalhado) | D20: 2 | E20: Pix
A21: 19 | B21: 1 | C21: Venda avulsa (item não detalhado) | D21: 8 | E21: Pix
A22: 20 | B22: 1 | C22: Venda avulsa (item não detalhado) | D22: 24 | E22: Dinheiro
... A32: 30 | B32: 1 | C32: Venda avulsa (item não detalhado) | D32: 39 | E32: Pix
A33: 31 | B33: 1 | C33: Venda avulsa (item não detalhado) | D33: 24 | E33: Pix | F33: valor com rasura, conferir
A34: 32 | B34: 1 | C34: Venda avulsa (item não detalhado) | D34: 16 | E34: Dinheiro
A35: 33 | B35: 1 | C35: Venda avulsa (item não detalhado) | D35: 15 | E35: Pix
A36: 34 | B36: 1 | C36: Venda avulsa (item não detalhado) | D36: 4 | E36: Pix
A37: 35 | B37: 1 | C37: Venda avulsa (item não detalhado) | D37: 11 | E37: Pix
A38: 36 | B38: 1 | C38: Venda avulsa (item não detalhado) | D38: 4 | E38: Pix
A39: 37 | B39: 1 | C39: Venda avulsa (item não detalhado) | D39: 5 | E39: Pix
A40: 38 | B40: 1 | C40: Venda avulsa (item não detalhado) | D40: 5 | E40: Dinheiro
A41: 39 | B41: 2 | C41: 1 caldo, 2 brincadeiras | D41: 14 | E41: Dinheiro
A42: 40 | B42: 2 | C42: 1 guaraviva, 1 salgado | D42: 9 | E42: Crédito
A43: 41 | B43: 2 | C43: 1 caldo | D43: 5 | E43: Pix
A44: 42 | B44: 2 | C44: 3 brincadeiras | D44: 12 | E44: Dinheiro | F44: forma de pagamento pouco legível, conferir
A45: 43 | B45: 2 | C45: 1 pastel, 1 cachorro-quente, 3 guaravita, 3 água, 1 salgado | D45: 38 | E45: Débito
A46: 44 | B46: 2 | C46: 1 salgado, 2 guaraná, 2 brincadeiras | D46: 17 | E46: Dinheiro
A47: 45 | B47: 2 | C47: 2 brincadeiras | D47: 8 | E47: Pix
A48: 46 | B48: 2 | C48: 2 doces | D48: 4 | E48: Pix
A49: 47 | B49: 2 | C49: 2 brincadeiras | D49: 8 | E49: Débito
...

Sheet Consumo Interno (Equipe)
A1: Consumo Interno (Equipe)
A2: Nº | B2: Página | C2: Nome / Função | D2: Itens Consumidos | E2: Valor (R$) | F2: Observação
A3: 1 | B3: 8 | C3: Rosemary (Prof.) | D3: 2 água com gás R$ 8,00, 2 vale bebida (não foi especificado), 2 cachorro-quente R$ 14,00, 2 pastéis R$ 14,00, 1 caldo verde R$ 5,00, 2 refrigerante R$ 14,00 e 1 água R$ 3,00 | E3: 58 | F3: Falta somar o valor da bebida não identificada
A4: 2 | B4: 8 | C4: Tassiane (Mediadora) | D4: 3 pastéis R$ 21,00, 1 cachorro-quente R$ 7,00, 2 H2O R$ 16,00, 5 brincadeiras R$ 20,00 | E4: 64 | F4: Não totalizado no caderno
A5: 3 | B5: 8 | C5: Haylane (Prof.) | D5: 2 guaravita R$ 8,00, 5 esfiha R$ 20,00, 1 canjica R$ 5,00, 3 coxinha R$ 15,00, 1 caldo R$ 5,00, 2 bolo R$ 4,00 | E5: 62 | F5: Não totalizado no caderno
A6: 4 | B6: 8 | C6: — (irmã da Elaine) | D6: Valor único anotado, referência à Elaine | E6: 14 | F6: Anotado como valor único
A7: 5 | B7: 8 | C7: Elaine O.P. | D7: 1 brincadeira R$ 4,00 + 1 água R$ 3,00 + 2 pastéis R$ 14,00 + 1 coca R$ 7,00 | E7: 32 | F7: '1 coca 7,00' anotado próximo
A8: 6 | B8: 8 | C8: Luciana Teles | D8: 1 água com gás R$ 4,00 + 1 coca R$ 7,00 + 1 coxinha R$ 5,00 | E8: 16
A9: 7 | B9: 8 | C9: Kesia | D9: 1 caldo R$ 5,00 | E9: 5
A10: 8 | B10: 8 | C10: Reny | D10: 1 caldo R$ 5,00 | E10: 5
A11: 9 | B11: 8 | C11: Tayane | D11: 1 água R$ 3,00 + 1 coca lata R$ 7,00 | E11: 11 | F11: valor da coca não totalizado
A12: 10 | B12: 8 | C12: Sulamita | D12: 1 brincadeira R$ 4,00 | E12: 4 | F12: anotação pouco legível
A13: 11 | B13: 8 | C13: Ana Paula | D13: 3 cachorro-quente R$ 21,00 + 2 pastéis R$ 14,00 + 2 refrigerante R$ 14,00 | E13: 49 | F13: '-29,00 / 2,00' anotado ao lado
A14: 12 | B14: 8 | C14: Adrielle (Monitora) | D14: 1 pastel R$ 7,00 + 3 brincadeiras R$ 12,00 | E14: 19 | F14: Anotado 'P/C' (por conta)
A15: 13 | B15: 8 | C15: Marcio | D15: 2 caldo 4,00 + 2 quites/refresco + 2 guaravita + 1 empadão + 3 cachorro-quente | E15: 0 | F15: não contar
A16: 14 | B16: 8 | C16: Felipe | D16: 1 cachorro-quente R$ 7,00 e 1 esfiha R$ 4,00 | E16: 11
A17: 15 | B17: 8 | C17: Jeovanna | D17: 1 coxinha R$ 5,00 e 1 empadão R$ 4,00 | E17: 9
A18: 16 | B18: 11 | C18: Rose (Insp.) | D18: 1 coca R$ 7,00, 1 guaravita R$ 4,00 | E18: 11
A19: 17 | B19: 11 | C19: Lu (Prof.) | D19: 1 guaravita R$ 4,00, 1 coca R$ 7,00 | E19: 0 | F19: nomes repetidos ou fora da folha; valor não totalizado
A20: 18 | B20: 11 | C20: Lili | D20: 1 salgado R$ 5,00 | E20: 0 | F20: valor não totalizado
A21: 19 | B21: 14 | C21: Rosemary (Prof.) | D21: 2 vale bebida, 1 cachorro-quente, 1 pastel, 1 caldo verde, 1 água com gás | E21: 0 | F21: repetição/confirmação da pág. 8
A22: 20 | B22: 14 | C22: Elaine D.P. | D22: — (irmã da Elaine) | E22: 14
A23: 21 | B23: 14 | C23: Elaine D.P. | D23: 3 coca R$ 7,00 | E23: 0 | F23: associado a Elaine
A24: 22 | B24: 14 | C24: Kenia | D24: 1 caldo R$ 5,00 | E24: 5
A25: 23 | B25: 14 | C25: Ana Paula | D25: 3 cachorro-quente R$ 14,00 + 2 pastel R$ 14,00 + 2 caixa de refri R$ 14,00 | E25: 33.8 | F25: '-29,80 / 2,00' anotado
A26: 24 | B26: 14 | C26: Adrielle (Monitora) | D26: 1 pastel + 3 brincadeiras | E26: 0 | F26: valor anotado como '06', pouco legível — conferir com pág. 8 (R$ 19,00)
A27: 25 | B27: 14 | C27: Marcio | D27: 2 caldo/carne 4,00 + 2 guaravita + 2 pêssego/refri capa + 1 empadão + 3 cachorro-quente | E27: 0
A28: 26 | B28: 14 | C28: Thayane | D28: 1 água 3,00 + 3 coca lata | E28: 0
A29: 27 | B29: 14 | C29: Sulamita | D29: 4 real pescaria | E29: 0
A30: 28 | B30: 14 | C30: Felix | D30: 1 cachorro-quente — junta R$ 7,00 | E30: 7
A31: 29 | B31: 16 | C31: Hanna | D31: 1 esfiha, 1 pastel, 4 coxinhas, 1 canjica | E31: 0 | F31: não totalizado
A32: 30 | B32: 16 | C32: Felipe (Mediador) | D32: 1 esfiha | E32: 0
A33: 31 | B33: 16 | C33: Giovanna | D33: 1 esfiha + salgado | E33: 0
A34: 32 | B34: 16 | C34: Haylane | D34: 5 esfiha + 1 canjica + 3 coxinhas | E34: 0
A35: 33 | B35: 16 | C35: Patrícia | D35: 1 coxinha | E35: 0 | F35: risco no nome — item cancelado?
A36: 34 | B36: 16 | C36: Mateus (motorista) | D36: 1 caldo | E36: 0
D37: TOTAL | E37: =SUM(E3:E36) -> 429.8

Sheet Extrato Maquininha
A1: Extrato Sequencial da Maquininha de Cartão (Imagem 15 — 'Máquina Elaine')
A2: Nº | B2: Valor (R$) | C2: Tipo | E2: Subtotal Débito | F2: =SUMIF(C3:C68,"Débito",B3:B68) -> 798.2
A3: 1 | B3: 18 | C3: Débito | E3: Subtotal Crédito | F3: =SUMIF(C3:C68,"Crédito",B3:B68) -> 343
A4: 2 | B4: 7.2 | C4: Débito
A5: 3 | B5: 29 | C5: Débito | E5: Observação: no topo da página consta a anotação '(17,57)' cuja relação com os lançamentos não está clara — conferir com o extrato oficial da maquininha (Elaine). O fechamento de caixa registra o total da maquininha como R$ 1.409,35 (valor oficial, pode divergir da soma manual dos lançamentos).
A6: 4 | B6: 18 | C6: Débito
A7: 5 | B7: 12 | C7: Débito
A8: 6 | B8: 15 | C8: Débito
A9: 7 | B9: 8 | C9: Débito
A10: 8 | B10: 18 | C10: Crédito
A11: 9 | B11: 8 | C11: Crédito
A12: 10 | B12: 16 | C12: Débito
A13: 11 | B13: 47 | C13: Crédito
A14: 12 | B14: 4 | C14: Crédito
A15: 13 | B15: 9 | C15: Crédito
A16: 14 | B16: 8 | C16: Débito
A17: 15 | B17: 19 | C17: Crédito
... A68: 66 | B68: 16 | C68: Crédito
A69: TOTAL | B69: =SUM(B3:B68) -> 1141.2

Sheet Doações
A1: Doações — Entrada Inicial de Caixa da Festa
A2: Nº | B2: Doador | C2: Valor (R$) | D2: Observação
A3: 1 | B3: Marbela Lanches | C3: 100 | D3: Doação informada por Mario (Diretor).
A4: 2 | B4: ETP | C4: 600 | D4: Doação informada por Mario (Diretor).
A5: 3 | B5: Colaboradores | C5: 200 | D5: Doação informada por Mario (Diretor).
B6: TOTAL DOAÇÕES | C6: =SUM(C3:C5) -> 900
A8: Nota: este valor é considerado uma entrada inicial de caixa para o início da festa (arrecadação prévia via doações de apoiadores). Por isso, ele é somado à Receita Bruta na aba 'Fechamento de Caixa' e no 'Resumo Geral' — não é uma venda realizada durante o evento, mas compõe o resultado líquido final.

Sheet Fechamento de Caixa
A1: Fechamento de Caixa (transcrição da Imagem 12, com doações e despesas atualizadas)
A2: Descrição | B2: Valor (R$) | C2: Observação
A3: Dinheiro em espécie | B3: 2086 | C3: Anotado 'Dinheiro: 2.086 em espécie' (dígito parcialmente rasurado no original — confirmar).
A4: Maquininha (Elaine) | B4: 1409.35 | C4: Anotado '1.409,35 máquina Elaine'.
A5: Pix da festa | B5: 2871.73 | C5: Anotado '2.871,73 Pix da festa'.
A6: Doações (entrada inicial da festa) | B6: =Doações!C6 -> 900 | C6: NOVO — ver aba 'Doações'. Considerado entrada de caixa no início da festa.
A7: RECEITA BRUTA (Dinheiro + Maquininha + Pix + Doações) | B7: =B3+B4+B5+B6 -> 7267.08 | C7: Receita bruta consolidada, já incluindo as doações como entrada inicial.
A9: Despesas descontadas no fechamento original:
A10: Tenda | B10: =-'Despesas da Festa'!C3 -> -200 | C10: Despesa descontada no fechamento original: 'Tenda: -200'.
A11: Foto | B11: =-'Despesas da Festa'!C4 -> -150 | C11: Despesa descontada no fechamento original: 'Foto: -150'.
A12: Alimentos complementares | B12: =-'Despesas da Festa'!C5 -> -315.49 | C12: Ver aba 'Despesas da Festa'.
A13: RESULTADO LÍQUIDO (conforme fechamento original, já com doações) | B13: =B7+B10+B11+B12 -> 6601.59 | C13: Receita bruta (com doações) menos as despesas originais do fechamento de caixa.
A15: Despesas adicionais informadas por Mario (não constavam no fechamento original):
A16: Vídeo Maker | B16: =-'Despesas da Festa'!C6 -> -150 | C16: Ver aba 'Despesas da Festa'.
A17: Tenda (adicional) | B17: =-'Despesas da Festa'!C7 -> -400 | C17: Ver aba 'Despesas da Festa'.
A18: Bebidas — custo líquido (sem Heineken e sem Chopp de Vinho, pagos à parte) | B18: =-'Despesas da Festa'!C12 -> -1128 | C18: NOVO — já com Heineken (R$268,00) e Chopp de Vinho Bodegão (R$113,40) retirados, por terem sido pagos à parte. Ver aba 'Despesas da Festa'.
A20: RESULTADO LÍQUIDO FINAL (com doações e despesas atualizadas) | B20: =B13+B16+B17+B18 -> 4923.59 | C20: Resultado final considerando doações como entrada inicial e as despesas de bebidas já sem Heineken/Chopp de Vinho.

Sheet Despesas da Festa
A1: Despesas Relacionadas à Festa (antes/depois do evento + fechamento de caixa)
A2: Nº | B2: Item | C2: Valor (R$) | D2: Incluir no Total? | E2: Observação
A3: 1 | B3: Tenda (registrada no fechamento de caixa original) | C3: 200 | D3: Sim | E3: Valor original anotado no caderno (Imagem 12): 'Tenda: -200'.
A4: 2 | B4: Foto | C4: 150 | D4: Sim | E4: Anotado no caderno (Imagem 12): 'Foto: -150'.
A5: 3 | B5: Alimentos complementares | C5: 315.49 | D5: Sim | E5: Alterado a pedido de Mario: originalmente anotado como 'Estephani mercado - R$315,49'; renomeado para 'Alimentos complementares'.
A6: 4 | B6: Vídeo Maker | C6: 150 | D6: Sim | E6: Despesa que antecedeu a festa — incluída a pedido de Mario (não constava nos cadernos originais).
A7: 5 | B7: Tenda (adicional) | C7: 400 | D7: Sim | E7: Despesa que antecedeu a festa — incluída a pedido de Mario (adicional à Tenda de R$200,00 já registrada no item 1; confirmar com Mario se são duas locações distintas ou se o valor de R$200 deveria ser substituído por este).
A8: 6 | B8: Nota Fiscal Bebidas — Loja Primavera (compra total, Venda nº 190686, 16/07/2026) | C8: 2062.4 | D8: Não | E8: Valor bruto da nota (Nota nº 01.852.665/0001-96). Não somado diretamente ao total — ver custo líquido no item 10, abaixo.
A9: 7 | B9: (-) Devolução de itens não utilizados (Nota Fiscal Bebidas) | C9: -553 | D9: Não | E9: Devolvidos ao fornecedor: 4 packs Coca-Cola lata c/12 (R$164,00) + 3 packs Fanta Laranja c/12 (R$120,00) + 3 packs Fanta Uva c/12 (R$120,00) + 2 packs Guaraná Antarctica c/12 (R$80,00) + 3 caixas Guaravita c/24 (R$69,00) = R$553,00. Ver imagem da nota na aba 'Notas Fiscais e Registros'.
A10: 8 | B10: (-) Cerveja Heineken (paga à parte) | C10: -268 | D10: Não | E10: Retirada do custo da festa a pedido de Mario — foi paga separadamente e NÃO deve ser somada ao total de despesas da festa.
A11: 9 | B11: (-) Chopp de Vinho Bodegão (pago à parte) | C11: -113.4 | D11: Não | E11: Retirado do custo da festa a pedido de Mario — foi pago separadamente e NÃO deve ser somado ao total de despesas da festa.
A12: 10 | B12: Bebidas — custo líquido considerado no total da festa | C12: =C8+C9+C10+C11 -> 1128 | D12: Sim | E12: Cálculo: Compra (R$2.062,40) − Devolução (R$553,00) − Heineken (R$268,00) − Chopp de Vinho (R$113,40).
B14: TOTAL DESPESAS (itens marcados 'Sim') | C14: =SUMIF(D3:D12,"Sim",C3:C12) -> 2343.49
A16: Nota: a Nota Fiscal de Bebidas (item 6), a devolução (item 7), a Heineken (item 8) e o Chopp de Vinho Bodegão (item 9) NÃO entram na soma do total — são apenas memória de cálculo. Apenas o item 10 (custo líquido das bebidas, já sem Heineken e sem Chopp de Vinho) é somado ao total de despesas da festa, pois esses dois itens foram pagos à parte, conforme solicitado por Mario.

Sheet Resumo Geral
A1: Resumo Geral da Arrecadação da Festa
A2: 1. Vendas por forma de pagamento (aba 'Vendas Detalhadas')
A3: Forma de Pagamento | B3: Total (R$)
A4: Pix | B4: =SUMIF('Vendas Detalhadas'!E3:E276,"Pix",'Vendas Detalhadas'!D3:D276) -> 1556
A5: Dinheiro | B5: =SUMIF('Vendas Detalhadas'!E3:E276,"Dinheiro",'Vendas Detalhadas'!D3:D276) -> 738.5
A6: Débito | B6: =SUMIF('Vendas Detalhadas'!E3:E276,"Débito",'Vendas Detalhadas'!D3:D276) -> 568
A7: Crédito | B7: =SUMIF('Vendas Detalhadas'!E3:E276,"Crédito",'Vendas Detalhadas'!D3:D276) -> 188
A8: Cartão | B8: =SUMIF('Vendas Detalhadas'!E3:E276,"Cartão",'Vendas Detalhadas'!D3:D276) -> 29
A9: — (forma não indicada) | B9: =SUMIF('Vendas Detalhadas'!E3:E276,"—",'Vendas Detalhadas'!D3:D276) -> 618
A10: Subtotal Vendas Detalhadas | B10: =SUM(B4:B9) -> 3697.5
A12: 2. Totais consolidados por origem
A13: Origem / Fonte | B13: Valor (R$) | C13: Observação
A14: Total 'Vendas Detalhadas' (soma de todas as linhas) | B14: ='Vendas Detalhadas'!D277 -> 3697.5 | C14: Soma de todas as vendas transcritas, todas as formas de pagamento.
A15: Total Extrato Maquininha (débito+crédito) | B15: ='Extrato Maquininha'!B69 -> 1141.2 | C15: Soma dos 66 lançamentos de débito/crédito transcritos da maquininha.
A16: Dinheiro em espécie (Fechamento de Caixa) | B16: ='Fechamento de Caixa'!B3 -> 2086
A17: Maquininha — valor final (Fechamento de Caixa) | B17: ='Fechamento de Caixa'!B4 -> 1409.35 | C17: Valor oficial de fechamento; pode divergir do somatório manual do extrato de lançamentos.
A18: Pix (Fechamento de Caixa) | B18: ='Fechamento de Caixa'!B5 -> 2871.73
A19: Doações (entrada inicial da festa) | B19: ='Fechamento de Caixa'!B6 -> 900 | C19: NOVO — ver aba 'Doações'. Somado à Receita Bruta abaixo, não é uma venda.
A21: 3. Despesas e Resultado Final
A22: Descrição | B22: Valor (R$) | C22: Observação
A23: Receita bruta (Dinheiro + Maquininha + Pix + Doações — Fechamento de Caixa) | B23: ='Fechamento de Caixa'!B7 -> 7267.08 | C23: Já inclui as doações como entrada inicial de caixa.
A24: Total de Despesas (aba 'Despesas da Festa' — Tenda, Foto, Alimentos complementares, Vídeo Maker, Tenda adicional e Bebidas — já sem Heineken/Chopp de Vinho) | B24: ='Despesas da Festa'!C14 -> 2343.49 | C24: Heineken (R$268,00) e Chopp de Vinho Bodegão (R$113,40) foram retirados por terem sido pagos à parte.
A25: RESULTADO LÍQUIDO FINAL DA FESTA | B25: ='Fechamento de Caixa'!B20 -> 4923.59 | C25: Receita bruta (com doações) menos o total de despesas atualizado.
A27: Nota: os valores desta aba são calculados por fórmula a partir das demais abas. Como as anotações originais possuem múltiplos métodos de registro (vendas linha a linha, consumo interno da equipe, extrato da maquininha e um fechamento de caixa resumido), os totais podem apresentar pequenas divergências entre si. Recomenda-se validar o resultado final com a Direção antes de publicar como prestação de contas oficial.

Sheet Notas Fiscais e Registros
A1: Notas Fiscais e Registros da Festa
A3: Esta aba reúne as imagens das notas fiscais e outros comprovantes/registros relacionados à festa, organizados em 'cartões'.
A7: COMO ADICIONAR UMA NOVA NOTA (no Excel): 1) Copie um dos cartões em branco abaixo (título + moldura). 2) Preencha Data, Fornecedor, Valor e Referente a. 3) Vá em Inserir > Imagens e selecione a foto da nota. 4) Arraste e redimensione a imagem para que fique dentro da moldura com borda azul.
A9: Dica: para manter a planilha leve, use fotos com boa legibilidade mas tamanho de arquivo moderado (evite fotos acima de 5-8 MB). Se preferir, envie a foto para o Claude e peça para inseri-la diretamente nesta aba.
A12: Nota/Registro Nº 1 — Nota Fiscal Bebidas — Loja Primavera
A13: Data: 16/07/2026
A14: Fornecedor: Loja Primavera (CNPJ 01.852.665/0001-96)
A15: Valor: R$ 2.062,40 (compra) / R$ 1.128,00 (custo líquido considerado no total da festa)
A16: Referente a: Compra de bebidas para a festa — Venda nº 190686
A17: [ Inserir imagem da nota/registro aqui — Inserir > Imagens ]
A18: Observações: Itens devolvidos ao fornecedor (não utilizados): 4 packs Coca-Cola lata c/12 (R$164,00) + 3 packs Fanta Laranja c/12 (R$120,00) + 3 packs Fanta Uva c/12 (R$120,00) + 2 packs Guaraná Antarctica c/12 (R$80,00) + 3 caixas Guaravita c/24 (R$69,00) = total devolvido R$553,00. Além disso, a cerveja Heineken (R$268,00) e o chopp de vinho Bodegão (R$113,40) foram pagos à parte e também não entram no custo considerado. Ver detalhamento completo na aba 'Despesas da Festa'.
A21: Nota/Registro Nº 2 — [preencher]
... A36: Observações:
